C++ 异常处理涉及到三个关键字：**try、catch、throw**。

- **throw:** 当问题出现时，程序会抛出一个异常。这是通过使用 **throw** 关键字来完成的。
- **catch:** 在您想要处理问题的地方，通过异常处理程序捕获异常。**catch** 关键字用于捕获异常。
- **try:** **try** 块中的代码标识将被激活的特定异常。它后面通常跟着一个或多个 catch 块。

# 实例

``` c++
#include <iostream>
using namespace std;
 
double division(int a, int b)
{
   if( b == 0 )
   {
      throw "Division by zero condition!";
   }
   return (a/b);
}
 
int main ()
{
   int x = 50;
   int y = 0;
   double z = 0;
 
   try {
     z = division(x, y);
     cout << z << endl;
   }catch (const char* msg) {
     cerr << msg << endl;
   }
 
   return 0;
}
```

#  C++ 标准异常

C++ 提供了一系列标准的异常，定义在 **<exception>** 中，我们可以在程序中使用这些标准的异常。它们是以父子类层次结构组织起来的，如下所示：

![1558883385021](E:\WorkSpace\notes\notes\c_c++\assets\1558883385021.png)

下表是对上面层次结构中出现的每个异常的说明：

| 异常                   | 描述                                                         |
| :--------------------- | :----------------------------------------------------------- |
| **std::exception**     | 该异常是所有标准 C++ 异常的父类。                            |
| std::bad_alloc         | 该异常可以通过 **new** 抛出。                                |
| std::bad_cast          | 该异常可以通过 **dynamic_cast** 抛出。                       |
| std::bad_exception     | 这在处理 C++ 程序中无法预期的异常时非常有用。                |
| std::bad_typeid        | 该异常可以通过 **typeid** 抛出。                             |
| **std::logic_error**   | 理论上可以通过读取代码来检测到的异常。                       |
| std::domain_error      | 当使用了一个无效的数学域时，会抛出该异常。                   |
| std::invalid_argument  | 当使用了无效的参数时，会抛出该异常。                         |
| std::length_error      | 当创建了太长的 std::string 时，会抛出该异常。                |
| std::out_of_range      | 该异常可以通过方法抛出，例如 std::vector 和 std::bitset<>::operator[]()。 |
| **std::runtime_error** | 理论上不可以通过读取代码来检测到的异常。                     |
| std::overflow_error    | 当发生数学上溢时，会抛出该异常。                             |
| std::range_error       | 当尝试存储超出范围的值时，会抛出该异常。                     |
| std::underflow_error   | 当发生数学下溢时，会抛出该异常。                             |

# 定义新的异常

您可以通过继承和重载 **exception** 类来定义新的异常。

``` c++
#include <iostream>
#include <exception>
using namespace std;
 
struct MyException : public exception
{
  const char * what () const throw ()
  {
    return "C++ Exception";
  }
};
 
int main()
{
  try
  {
    throw MyException();
  }
  catch(MyException& e)
  {
    std::cout << "MyException caught" << std::endl;
    std::cout << e.what() << std::endl;
  }
  catch(std::exception& e)
  {
    //其他的错误
  }
}
```

在这里，**what()** 是异常类提供的一个公共方法，它已被所有子异常类重载。这将返回异常产生的原因。